Workbook
Name B82C81: Export_Statistical!$B$82

Sheet Export-dataset
A1: Export | B1: 0 Food and live animals ; | C1: 00 Live animals (excl. fish (not marine mammals) crustaceans, molluscs and aquatic invertebrates of SITC Division 03) ; | D1: 01 Meat and meat preparations ; | E1: 02 Dairy products and birds’ eggs ; | F1: 03 Fish (excl. marine mammals) crustaceans, molluscs and aquatic invertebrates, and preparations thereof (excl. extracts and juices of fish, crustaceans, molluscs or other aquatic invertebrates, prepared or preserved of SITC 01710) ; | G1: 04 Cereals and cereal preparations ; | H1: 05 Vegetables and fruit ; | I1: 06 Sugars, sugar preparations and honey ; | J1: 07 Coffee, tea, cocoa, spices, and manufactures thereof ; | K1: 08 Feeding stuff for animals (excl. unmilled cereals) ; | L1: 09 Miscellaneous edible products and preparations ; | M1: 1 Beverages and tobacco ; | N1: 11 Beverages ; | O1: 12 Tobacco and tobacco manufactures ; | P1: 2 Crude materials, inedible, except fuels ; | Q1: 21 Hides, skins and furskins, raw ; | R1: 22 Oil-seeds and oleaginous fruits ; | S1: 23 Crude rubber (incl. synthetic and reclaimed) ; | T1: 24 Cork and wood ; | U1: 25 Pulp and waste paper ; | V1: 26 Textile fibres (excl. wool tops and other combed wool) and their wastes, not manufactured into yarn or fabric ; | W1: 27 Crude fertilizers (excl. those of Division 56) and crude minerals (excl. coal, petroleum and precious stones) ; | X1: 28 Metalliferous ores and metal scrap ; | Y1: 29 Crude animal and vegetable materials, nes ; | Z1: 3 Mineral fuels, lubricants and related materials ; | AA1: 31 Coal, coke and briquettes ; | AB1: 32 Petroleum, petroleum products and related materials ; | AC1: 33 Gas, natural and manufactured ; | AD1: 4 Animal and vegetable oils, fats and waxes ; | AE1: 41 Animal oils and fats ; | AF1: 42 Fixed vegetable fats and oils, crude, refined or fractionated ; | AG1: 43 Animal or vegetable fats and oils, processed; waxes of animal or vegetable origin; inedible mixtures or preparations of animal or vegetable fats or oils, nes ; | AH1: 5 Chemicals and related products, nes ; | AI1: 51 Organic chemicals ; | AJ1: 52 Inorganic chemicals ; | AK1: 53 Dyeing, tanning and colouring materials ; | AL1: 54 Medicinal and pharmaceutical products ; | AM1: 55 Essential oils and resinoids and perfume materials; toilet, polishing and cleansing preparations ; | AN1: 56 Fertilisers (excl. those of group 272) ; | AO1: 57 Plastics in primary forms ; | AP1: 58 Plastics in non-primary forms ; | AQ1: 59 Chemical materials and products, nes ; | AR1: 6 Manufactured goods classified chiefly by material ; | AS1: 61 Leather, leather manufactures, nes, and dressed furskins ; | AT1: 62 Rubber manufactures, nes ; | AU1: 63 Cork and wood manufactures (excl. furniture) ; | AV1: 64 Paper, paperboard and articles of paper pulp, of paper or of paperboard ; | AW1: 65 Textile yarn, fabrics, made-up articles nes, and related products ; | AX1: 66 Non-metallic mineral manufactures, nes ; | AY1: 67 Iron and steel ; | AZ1: 68 Non-ferrous metals ; | BA1: 69 Manufactures of metals, nes ; | BB1: 7 Machinery and transport equipment ; | BC1: 71 Power generating machinery and equipment ; | BD1: 72 Machinery specialized for particular industries ; | BE1: 73 Metalworking machinery ; | BF1: 74 General industrial machinery and equipment, nes, and machine parts, nes ; | BG1: 75 Office machines and automatic data processing machines ; | BH1: 76 Telecommunications and sound recording and reproducing apparatus and equipment ; | BI1: 77 Electrical machinery, apparatus and appliances, nes, and electrical parts thereof (incl. non electrical counterparts, nes, of electrical household type equipment) ; | BJ1: 78 Road vehicles (incl. air-cushion vehicles) ; | BK1: 79 Transport equipment (excl. road vehicles) ; | BL1: 8 Miscellaneous manufactured articles ; | BM1: 81 Prefabricated buildings and sanitary, plumbing, heating and lighting fixtures and fittings, nes ; | BN1: 82 Furniture and parts thereof; bedding, mattresses, mattress supports, cushions and similar stuffed furnishings ; | BO1: 83 Travel goods, handbags and similar containers ; | BP1: 84 Articles of apparel and clothing accessories ; | BQ1: 85 Footwear ; | BR1: 87 Professional, scientific and controlling instruments and apparatus, nes ; | BS1: 88 Photographic apparatus, equipment and supplies and optical goods, nes; watches and clocks ; | BT1: 89 Miscellaneous manufactured articles, nes ; | BU1: 9 Commodities and transactions not classified elsewhere in the SITC ; | BV1: 91 Special transactions and commodities not classified according to kind ; | BW1: 92 Gold coin whether or not legal tender, and other coin being legal tender ; | BX1: 93 Coin (excl. gold coin) not being legal tender ; | BY1: 94 Gold, non-monetary (excl. gold ores and concentrates) ; | BZ1: 95 Combined confidential items excluding some of SITC 28099 (exports only) and some of SITC 51099 (imports only) ; | CA1: -1 TOTAL ;
A2: Unit | B2: $ Millions | C2: $ Millions | D2: $ Millions | E2: $ Millions | F2: $ Millions | G2: $ Millions | H2: $ Millions | I2: $ Millions | J2: $ Millions | K2: $ Millions | L2: $ Millions | M2: $ Millions | N2: $ Millions | O2: $ Millions | P2: $ Millions | Q2: $ Millions | R2: $ Millions | S2: $ Millions | T2: $ Millions | U2: $ Millions | V2: $ Millions | W2: $ Millions | X2: $ Millions | Y2: $ Millions | Z2: $ Millions | AA2: $ Millions | AB2: $ Millions | AC2: $ Millions | AD2: $ Millions | AE2: $ Millions | AF2: $ Millions | AG2: $ Millions | AH2: $ Millions | AI2: $ Millions | AJ2: $ Millions | AK2: $ Millions | AL2: $ Millions | AM2: $ Millions | AN2: $ Millions | AO2: $ Millions | AP2: $ Millions | AQ2: $ Millions | AR2: $ Millions | AS2: $ Millions | AT2: $ Millions | AU2: $ Millions | AV2: $ Millions | AW2: $ Millions | AX2: $ Millions | AY2: $ Millions | AZ2: $ Millions | BA2: $ Millions | BB2: $ Millions | BC2: $ Millions | BD2: $ Millions | BE2: $ Millions | BF2: $ Millions | BG2: $ Millions | BH2: $ Millions | BI2: $ Millions | BJ2: $ Millions | BK2: $ Millions | BL2: $ Millions | BM2: $ Millions | BN2: $ Millions | BO2: $ Millions | BP2: $ Millions | BQ2: $ Millions | BR2: $ Millions | BS2: $ Millions | BT2: $ Millions | BU2: $ Millions | BV2: $ Millions | BW2: $ Millions | BX2: $ Millions | BY2: $ Millions | BZ2: $ Millions | CA2: $ Millions
A3: Series ID | B3: A1827804K | C3: A1827805L | D3: A1827806R | E3: A1827807T | F3: A1827808V | G3: A1827809W | H3: A1827810F | I3: A1827811J | J3: A1827812K | K3: A1827813L | L3: A1827814R | M3: A1827815T | N3: A1827816V | O3: A1827817W | P3: A1827818X | Q3: A1827819A | R3: A1827820K | S3: A1827821L | T3: A1827822R | U3: A1827823T | V3: A1827824V | W3: A1827825W | X3: A1827826X | Y3: A1827827A | Z3: A1827828C | AA3: A1827829F | AB3: A1827830R | AC3: A1827831T | AD3: A1827832V | AE3: A1827833W | AF3: A1827834X | AG3: A1827835A | AH3: A1827836C | AI3: A1827837F | AJ3: A1827838J | AK3: A1827839K | AL3: A1827840V | AM3: A1827841W | AN3: A1827842X | AO3: A1827843A | AP3: A1827844C | AQ3: A1827845F | AR3: A1827846J | AS3: A1827847K | AT3: A1827848L | AU3: A1827849R | AV3: A1827850X | AW3: A1827851A | AX3: A1827852C | AY3: A1827853F | AZ3: A1827854J | BA3: A1827855K | BB3: A1827856L | BC3: A1827857R | BD3: A1827858T | BE3: A1827859V | BF3: A1827860C | BG3: A1827861F | BH3: A1827862J | BI3: A1827863K | BJ3: A1827864L | BK3: A1827865R | BL3: A1827866T | BM3: A1827867V | BN3: A1827868W | BO3: A1827869X | BP3: A1827870J | BQ3: A1827871K | BR3: A1827872L | BS3: A1827873R | BT3: A1827874T | BU3: A1827875V | BV3: A1827876W | BW3: A1827877X | BX3: A1827878A | BY3: A1827879C | BZ3: A1827880L | CA3: A1827881R
A4: Y1988 | B4: 7903 | C4: 322 | D4: 2423 | E4: 529 | F4: 663 | G4: 2071 | H4: 604 | I4: 859 | J4: 68 | K4: 273 | L4: 91 | M4: 272 | N4: 250 | O4: 22 | P4: 13373 | Q4: 614 | R4: 63 | S4: 10 | T4: 439 | U4: 37 | V4: 6270 | W4: 221 | X4: 5595 | Y4: 124 | Z4: 6461 | AA4: 4636 | AB4: 1615 | AC4: 210 | AD4: 146 | AE4: 122 | AF4: 14 | AG4: 10 | AH4: 1041 | AI4: 102 | AJ4: 86 | AK4: 109 | AL4: 229 | AM4: 89 | AN4: 9 | AO4: 157 | AP4: 61 | AQ4: 199 | AR4: 5344 | AS4: 165 | AT4: 72 | AU4: 15 | AV4: 116 | AW4: 148 | AX4: 318 | AY4: 501 | AZ4: 3703 | BA4: 306 | BB4: 2744 | BC4: 366 | BD4: 336 | BE4: 39 | BF4: 322 | BG4: 406 | BH4: 142 | BI4: 280 | BJ4: 392 | BK4: 461 | BL4: 1075 | BM4: 31 | BN4: 36 | BO4: 2 | BP4: 65 | BQ4: 14 | BR4: 196 | BS4: 277 | BT4: 454 | BU4: 4006 | BV4: 156 | BW4: 196 | BX4: 1 | BY4: 2674 | BZ4: 979 | CA4: 42365
A5: Y1989 | B5: 9487 | C5: 244 | D5: 2639 | E5: 682 | F5: 646 | G5: 3205 | H5: 514 | I5: 1128 | J5: 65 | K5: 267 | L5: 97 | M5: 228 | N5: 211 | O5: 17 | P5: 14124 | Q5: 515 | R5: 44 | S5: 14 | T5: 409 | U5: 33 | V5: 5642 | W5: 206 | X5: 7128 | Y5: 133 | Z5: 7234 | AA5: 5314 | AB5: 1660 | AC5: 260 | AD5: 111 | AE5: 100 | AF5: 1 | AG5: 10 | AH5: 1174 | AI5: 90 | AJ5: 117 | AK5: 236 | AL5: 246 | AM5: 92 | AN5: 9 | AO5: 145 | AP5: 57 | AQ5: 182 | AR5: 6063 | AS5: 151 | AT5: 62 | AU5: 13 | AV5: 137 | AW5: 168 | AX5: 447 | AY5: 584 | AZ5: 4153 | BA5: 348 | BB5: 3286 | BC5: 378 | BD5: 382 | BE5: 54 | BF5: 351 | BG5: 480 | BH5: 219 | BI5: 327 | BJ5: 508 | BK5: 587 | BL5: 1257 | BM5: 28 | BN5: 35 | BO5: 3 | BP5: 88 | BQ5: 23 | BR5: 241 | BS5: 250 | BT5: 589 | BU5: 4035 | BV5: 153 | BW5: 205 | BX5: 0 | BY5: 2590 | BZ5: 1087 | CA5: 46999
A6: Y1990 | B6: 9726 | C6: 163 | D6: 3090 | E6: 676 | F6: 676 | G6: 3014 | H6: 581 | I6: 1101 | J6: 82 | K6: 238 | L6: 105 | M6: 285 | N6: 266 | O6: 19 | P6: 13461 | Q6: 528 | R6: 51 | S6: 8 | T6: 402 | U6: 21 | V6: 3939 | W6: 240 | X6: 8113 | Y6: 159 | Z6: 9596 | AA6: 6024 | AB6: 2882 | AC6: 690 | AD6: 126 | AE6: 113 | AF6: 1 | AG6: 12 | AH6: 1295 | AI6: 106 | AJ6: 175 | AK6: 221 | AL6: 293 | AM6: 105 | AN6: 12 | AO6: 136 | AP6: 76 | AQ6: 171 | AR6: 6257 | AS6: 180 | AT6: 67 | AU6: 33 | AV6: 168 | AW6: 196 | AX6: 464 | AY6: 909 | AZ6: 3833 | BA6: 407 | BB6: 4117 | BC6: 490 | BD6: 459 | BE6: 80 | BF6: 430 | BG6: 635 | BH6: 291 | BI6: 413 | BJ6: 736 | BK6: 583 | BL6: 1306 | BM6: 37 | BN6: 42 | BO6: 5 | BP6: 125 | BQ6: 22 | BR6: 252 | BS6: 241 | BT6: 582 | BU6: 4723 | BV6: 186 | BW6: 250 | BX6: 2 | BY6: 3440 | BZ6: 845 | CA6: 50892
A7: Y1991 | B7: 9311 | C7: 182 | D7: 3239 | E7: 793 | F7: 739 | G7: 2411 | H7: 651 | I7: 765 | J7: 92 | K7: 304 | L7: 135 | M7: 334 | N7: 313 | O7: 21 | P7: 13673 | Q7: 346 | R7: 59 | S7: 8 | T7: 461 | U7: 20 | V7: 4371 | W7: 290 | X7: 7955 | Y7: 163 | Z7: 10877 | AA7: 6857 | AB7: 2915 | AC7: 1105 | AD7: 136 | AE7: 117 | AF7: 1 | AG7: 18 | AH7: 1531 | AI7: 106 | AJ7: 253 | AK7: 188 | AL7: 381 | AM7: 125 | AN7: 17 | AO7: 181 | AP7: 82 | AQ7: 198 | AR7: 6484 | AS7: 187 | AT7: 67 | AU7: 50 | AV7: 209 | AW7: 218 | AX7: 556 | AY7: 1027 | AZ7: 3621 | BA7: 549 | BB7: 4862 | BC7: 566 | BD7: 523 | BE7: 79 | BF7: 511 | BG7: 808 | BH7: 317 | BI7: 542 | BJ7: 820 | BK7: 696 | BL7: 1423 | BM7: 38 | BN7: 36 | BO7: 2 | BP7: 142 | BQ7: 30 | BR7: 311 | BS7: 260 | BT7: 604 | BU7: 5074 | BV7: 197 | BW7: 321 | BX7: 0 | BY7: 3702 | BZ7: 854 | CA7: 53705
A8: Y1992 | B8: 10585 | C8: 226 | D8: 3669 | E8: 957 | F8: 913 | G8: 2449 | H8: 825 | I8: 888 | J8: 112 | K8: 405 | L8: 141 | M8: 377 | N8: 355 | O8: 22 | P8: 13497 | Q8: 398 | R8: 61 | S8: 11 | T8: 419 | U8: 9 | V8: 4539 | W8: 328 | X8: 7539 | Y8: 193 | Z8: 11612 | AA8: 7345 | AB8: 3123 | AC8: 1144 | AD8: 154 | AE8: 131 | AF8: 1 | AG8: 22 | AH8: 1817 | AI8: 77 | AJ8: 195 | AK8: 297 | AL8: 517 | AM8: 155 | AN8: 15 | AO8: 192 | AP8: 94 | AQ8: 275 | AR8: 7078 | AS8: 259 | AT8: 98 | AU8: 61 | AV8: 247 | AW8: 268 | AX8: 603 | AY8: 1179 | AZ8: 3816 | BA8: 547 | BB8: 5721 | BC8: 614 | BD8: 629 | BE8: 95 | BF8: 618 | BG8: 904 | BH8: 401 | BI8: 656 | BJ8: 887 | BK8: 917 | BL8: 1772 | BM8: 91 | BN8: 45 | BO8: 4 | BP8: 175 | BQ8: 36 | BR8: 367 | BS8: 338 | BT8: 716 | BU8: 5759 | BV8: 203 | BW8: 289 | BX8: 0 | BY8: 4476 | BZ8: 791 | CA8: 58372
A9: Y1993 | B9: 12435 | C9: 289 | D9: 3958 | E9: 1169 | F9: 1058 | G9: 3102 | H9: 912 | I9: 1210 | J9: 146 | K9: 430 | L9: 161 | M9: 492 | N9: 457 | O9: 35 | P9: 12753 | Q9: 378 | R9: 84 | S9: 10 | T9: 531 | U9: 13 | V9: 3662 | W9: 370 | X9: 7499 | Y9: 206 | Z9: 11983 | AA9: 7798 | AB9: 2964 | AC9: 1221 | AD9: 209 | AE9: 173 | AF9: 2 | AG9: 34 | AH9: 2189 | AI9: 83 | AJ9: 221 | AK9: 354 | AL9: 639 | AM9: 191 | AN9: 14 | AO9: 211 | AP9: 111 | AQ9: 365 | AR9: 7575 | AS9: 327 | AT9: 117 | AU9: 88 | AV9: 253 | AW9: 355 | AX9: 580 | AY9: 1380 | AZ9: 3895 | BA9: 580 | BB9: 7020 | BC9: 624 | BD9: 801 | BE9: 97 | BF9: 817 | BG9: 1169 | BH9: 436 | BI9: 886 | BJ9: 1096 | BK9: 1094 | BL9: 2000 | BM9: 46 | BN9: 75 | BO9: 10 | BP9: 222 | BQ9: 52 | BR9: 388 | BS9: 445 | BT9: 762 | BU9: 6093 | BV9: 295 | BW9: 222 | BX9: 0 | BY9: 4683 | BZ9: 893 | CA9: 62749
A10: Y1994 | B10: 13394 | C10: 359 | D10: 3799 | E10: 1423 | F10: 1092 | G10: 3340 | H10: 926 | I10: 1672 | J10: 173 | K10: 403 | L10: 207 | M10: 531 | N10: 493 | O10: 38 | P10: 13074 | Q10: 452 | R10: 128 | S10: 12 | T10: 531 | U10: 27 | V10: 4287 | W10: 352 | X10: 7074 | Y10: 211 | Z10: 10671 | AA10: 6750 | AB10: 2705 | AC10: 1216 | AD10: 223 | AE10: 184 | AF10: 7 | AG10: 32 | AH10: 2467 | AI10: 85 | AJ10: 277 | AK10: 372 | AL10: 729 | AM10: 235 | AN10: 23 | AO10: 209 | AP10: 123 | AQ10: 414 | AR10: 8280 | AS10: 426 | AT10: 126 | AU10: 89 | AV10: 253 | AW10: 417 | AX10: 787 | AY10: 1505 | AZ10: 3994 | BA10: 683 | BB10: 7606 | BC10: 602 | BD10: 806 | BE10: 120 | BF10: 935 | BG10: 1509 | BH10: 689 | BI10: 1088 | BJ10: 1014 | BK10: 843 | BL10: 2235 | BM10: 48 | BN10: 75 | BO10: 13 | BP10: 288 | BQ10: 56 | BR10: 444 | BS10: 483 | BT10: 828 | BU10: 6281 | BV10: 381 | BW10: 246 | BX10: 0 | BY10: 4671 | BZ10: 983 | CA10: 64762
A11: Y1995 | B11: 13073 | C11: 576 | D11: 3539 | E11: 1495 | F11: 1160 | G11: 2689 | H11: 921 | I11: 1877 | J11: 181 | K11: 412 | L11: 223 | M11: 585 | N11: 542 | O11: 43 | P11: 14647 | Q11: 492 | R11: 122 | S11: 13 | T11: 647 | U11: 47 | V11: 4404 | W11: 427 | X11: 8270 | Y11: 225 | Z11: 11980 | AA11: 7433 | AB11: 3029 | AC11: 1518 | AD11: 256 | AE11: 216 | AF11: 2 | AG11: 38 | AH11: 2908 | AI11: 80 | AJ11: 356 | AK11: 425 | AL11: 834 | AM11: 279 | AN11: 29 | AO11: 340 | AP11: 159 | AQ11: 406 | AR11: 9791 | AS11: 504 | AT11: 151 | AU11: 103 | AV11: 280 | AW11: 518 | AX11: 680 | AY11: 1767 | AZ11: 5094 | BA11: 694 | BB11: 9164 | BC11: 799 | BD11: 1063 | BE11: 142 | BF11: 1015 | BG11: 1753 | BH11: 689 | BI11: 1359 | BJ11: 1126 | BK11: 1218 | BL11: 2496 | BM11: 65 | BN11: 86 | BO11: 12 | BP11: 302 | BQ11: 63 | BR11: 469 | BS11: 530 | BT11: 969 | BU11: 6785 | BV11: 424 | BW11: 163 | BX11: 0 | BY11: 5263 | BZ11: 935 | CA11: 71685
A12: Y1996 | B12: 15804 | C12: 659 | D12: 2892 | E12: 1760 | F12: 1050 | G12: 5761 | H12: 1084 | I12: 1649 | J12: 196 | K12: 500 | L12: 253 | M12: 740 | N12: 677 | O12: 63 | P12: 15023 | Q12: 496 | R12: 218 | S12: 12 | T12: 621 | U12: 14 | V12: 4285 | W12: 384 | X12: 8771 | Y12: 222 | Z12: 13002 | AA12: 7818 | AB12: 3508 | AC12: 1676 | AD12: 237 | AE12: 194 | AF12: 10 | AG12: 33 | AH12: 3001 | AI12: 91 | AJ12: 333 | AK12: 420 | AL12: 942 | AM12: 300 | AN12: 23 | AO12: 299 | AP12: 153 | AQ12: 440 | AR12: 9429 | AS12: 471 | AT12: 159 | AU12: 109 | AV12: 343 | AW12: 566 | AX12: 770 | AY12: 1623 | AZ12: 4619 | BA12: 769 | BB12: 9955 | BC12: 878 | BD12: 1089 | BE12: 200 | BF12: 1219 | BG12: 1781 | BH12: 655 | BI12: 1347 | BJ12: 1538 | BK12: 1248 | BL12: 2813 | BM12: 85 | BN12: 99 | BO12: 14 | BP12: 339 | BQ12: 64 | BR12: 596 | BS12: 578 | BT12: 1038 | BU12: 6987 | BV12: 508 | BW12: 126 | BX12: 0 | BY12: 5236 | BZ12: 1117 | CA12: 76991
A13: Y1997 | B13: 17197 | C13: 743 | D13: 3442 | E13: 1834 | F13: 1203 | G13: 6042 | H13: 1156 | I13: 1723 | J13: 193 | K13: 558 | L13: 303 | M13: 890 | N13: 835 | O13: 55 | P13: 17150 | Q13: 546 | R13: 255 | S13: 11 | T13: 683 | U13: 19 | V13: 5225 | W13: 383 | X13: 9801 | Y13: 227 | Z13: 14966 | AA13: 8821 | AB13: 4102 | AC13: 2043 | AD13: 270 | AE13: 196 | AF13: 30 | AG13: 44 | AH13: 3213 | AI13: 143 | AJ13: 328 | AK13: 439 | AL13: 1058 | AM13: 298 | AN13: 21 | AO13: 318 | AP13: 162 | AQ13: 446 | AR13: 9917 | AS13: 510 | AT13: 163 | AU13: 107 | AV13: 416 | AW13: 626 | AX13: 783 | AY13: 1666 | AZ13: 4897 | BA13: 749 | BB13: 11314 | BC13: 1035 | BD13: 1189 | BE13: 221 | BF13: 1146 | BG13: 1674 | BH13: 987 | BI13: 1262 | BJ13: 1869 | BK13: 1931 | BL13: 3051 | BM13: 87 | BN13: 97 | BO13: 14 | BP13: 376 | BQ13: 59 | BR13: 710 | BS13: 665 | BT13: 1043 | BU13: 6802 | BV13: 530 | BW13: 128 | BX13: 1 | BY13: 4923 | BZ13: 1220 | CA13: 84770
A14: Y1998 | B14: 15152 | C14: 567 | D14: 3911 | E14: 2142 | F14: 1178 | G14: 5017 | H14: 1135 | I14: 180 | J14: 176 | K14: 545 | L14: 301 | M14: 1154 | N14: 1084 | O14: 70 | P14: 17908 | Q14: 510 | R14: 452 | S14: 10 | T14: 699 | U14: 22 | V14: 4503 | W14: 449 | X14: 11015 | Y14: 248 | Z14: 15078 | AA14: 9849 | AB14: 3374 | AC14: 1855 | AD14: 385 | AE14: 265 | AF14: 70 | AG14: 50 | AH14: 3388 | AI14: 139 | AJ14: 316 | AK14: 525 | AL14: 1225 | AM14: 283 | AN14: 32 | AO14: 237 | AP14: 164 | AQ14: 467 | AR14: 10428 | AS14: 497 | AT14: 169 | AU14: 104 | AV14: 421 | AW14: 593 | AX14: 698 | AY14: 1826 | AZ14: 5418 | BA14: 702 | BB14: 10656 | BC14: 808 | BD14: 1365 | BE14: 181 | BF14: 1034 | BG14: 1565 | BH14: 862 | BI14: 1277 | BJ14: 1863 | BK14: 1701 | BL14: 3345 | BM14: 85 | BN14: 98 | BO14: 12 | BP14: 365 | BQ14: 62 | BR14: 872 | BS14: 671 | BT14: 1180 | BU14: 11493 | BV14: 766 | BW14: 135 | BX14: 2 | BY14: 7642 | BZ14: 2948 | CA14: 88987
A15: Y1999 | B15: 15878 | C15: 698 | D15: 4163 | E15: 2209 | F15: 1387 | G15: 4882 | H15: 1192 | I15: 164 | J15: 213 | K15: 626 | L15: 344 | M15: 1402 | N15: 1345 | O15: 57 | P15: 16669 | Q15: 343 | R15: 777 | S15: 13 | T15: 698 | U15: 30 | V15: 3972 | W15: 415 | X15: 10164 | Y15: 257 | Z15: 14460 | AA15: 8406 | AB15: 4174 | AC15: 1880 | AD15: 328 | AE15: 226 | AF15: 51 | AG15: 51 | AH15: 3855 | AI15: 159 | AJ15: 380 | AK15: 524 | AL15: 1481 | AM15: 334 | AN15: 31 | AO15: 232 | AP15: 178 | AQ15: 536 | AR15: 10684 | AS15: 430 | AT15: 180 | AU15: 138 | AV15: 470 | AW15: 604 | AX15: 868 | AY15: 1362 | AZ15: 5974 | BA15: 658 | BB15: 10988 | BC15: 793 | BD15: 1096 | BE15: 197 | BF15: 1029 | BG15: 1405 | BH15: 906 | BI15: 1298 | BJ15: 2441 | BK15: 1823 | BL15: 3618 | BM15: 77 | BN15: 127 | BO15: 12 | BP15: 331 | BQ15: 63 | BR15: 1004 | BS15: 784 | BT15: 1220 | BU15: 9018 | BV15: 1807 | BW15: 98 | BX15: 8 | BY15: 4810 | BZ15: 2295 | CA15: 86900
... A39: Y2023 | B39: 54927 | C39: 1239 | D39: 17910 | E39: 3010 | F39: 1351 | G39: 20643 | H39: 5915 | I39: 294 | J39: 497 | K39: 1746 | L39: 2322 | M39: 2569 | N39: 2545 | O39: 24 | P39: 202833 | Q39: 454 | R39: 5507 | S39: 14 | T39: 1442 | U39: 206 | V39: 7452 | W39: 19318 | X39: 167787 | Y39: 653 | Z39: 194429 | AA39: 101958 | AB39: 15802 | AC39: 76669 | AD39: 1610 | AE39: 1052 | AF39: 422 | AG39: 136 | AH39: 11510 | AI39: 223 | AJ39: 1263 | AK39: 924 | AL39: 4753 | AM39: 1695 | AN39: 338 | AO39: 266 | AP39: 387 | AQ39: 1661 | AR39: 19417 | AS39: 111 | AT39: 398 | AU39: 99 | AV39: 893 | AW39: 366 | AX39: 858 | AY39: 1166 | AZ39: 14075 | BA39: 1451 | BB39: 18668 | BC39: 1303 | BD39: 2127 | BE39: 273 | BF39: 3059 | BG39: 1488 | BH39: 2683 | BI39: 2963 | BJ39: 2190 | BK39: 2582 | BL39: 10537 | BM39: 170 | BN39: 189 | BO39: 189 | BP39: 702 | BQ39: 183 | BR39: 4878 | BS39: 578 | BT39: 3648 | BU39: 41294 | BV39: 616 | BW39: 2011 | BX39: 11 | BY39: 28353 | BZ39: 10303 | CA39: 557794

Sheet Import-dataset
A1: Import | B1: 0 Food and live animals ; | C1: 00 Live animals (excl. fish (not marine mammals) crustaceans, molluscs and aquatic invertebrates of SITC Division 03) ; | D1: 01 Meat and meat preparations ; | E1: 02 Dairy products and birds’ eggs ; | F1: 03 Fish (excl. marine mammals) crustaceans, molluscs and aquatic invertebrates, and preparations thereof (excl. extracts and juices of fish, crustaceans, molluscs or other aquatic invertebrates, prepared or preserved of SITC 01710) ; | G1: 04 Cereals and cereal preparations ; | H1: 05 Vegetables and fruit ; | I1: 06 Sugars, sugar preparations and honey ; | J1: 07 Coffee, tea, cocoa, spices, and manufactures thereof ; | K1: 08 Feeding stuff for animals (excl. unmilled cereals) ; | L1: 09 Miscellaneous edible products and preparations ; | M1: 1 Beverages and tobacco ; | N1: 11 Beverages ; | O1: 12 Tobacco and tobacco manufactures ; | P1: 2 Crude materials, inedible, except fuels ; | Q1: 21 Hides, skins and furskins, raw ; | R1: 22 Oil-seeds and oleaginous fruits ; | S1: 23 Crude rubber (incl. synthetic and reclaimed) ; | T1: 24 Cork and wood ; | U1: 25 Pulp and waste paper ; | V1: 26 Textile fibres (excl. wool tops and other combed wool) and their wastes, not manufactured into yarn or fabric ; | W1: 27 Crude fertilizers (excl. those of Division 56) and crude minerals (excl. coal, petroleum and precious stones) ; | X1: 28 Metalliferous ores and metal scrap ; | Y1: 29 Crude animal and vegetable materials, nes ; | Z1: 3 Mineral fuels, lubricants and related materials ; | AA1: 31 Coal, coke and briquettes ; | AB1: 32 Petroleum, petroleum products and related materials ; | AC1: 33 Gas, natural and manufactured ; | AD1: 4 Animal and vegetable oils, fats and waxes ; | AE1: 41 Animal oils and fats ; | AF1: 42 Fixed vegetable fats and oils, crude, refined or fractionated ; | AG1: 43 Animal or vegetable fats and oils, processed; waxes of animal or vegetable origin; inedible mixtures or preparations of animal or vegetable fats or oils, nes ; | AH1: 5 Chemicals and related products, nes ; | AI1: 51 Organic chemicals ; | AJ1: 52 Inorganic chemicals ; | AK1: 53 Dyeing, tanning and colouring materials ; | AL1: 54 Medicinal and pharmaceutical products ; | AM1: 55 Essential oils and resinoids and perfume materials; toilet, polishing and cleansing preparations ; | AN1: 56 Fertilisers (excl. those of group 272) ; | AO1: 57 Plastics in primary forms ; | AP1: 58 Plastics in non-primary forms ; | AQ1: 59 Chemical materials and products, nes ; | AR1: 6 Manufactured goods classified chiefly by material ; | AS1: 61 Leather, leather manufactures, nes, and dressed furskins ; | AT1: 62 Rubber manufactures, nes ; | AU1: 63 Cork and wood manufactures (excl. furniture) ; | AV1: 64 Paper, paperboard and articles of paper pulp, of paper or of paperboard ; | AW1: 65 Textile yarn, fabrics, made-up articles nes, and related products ; | AX1: 66 Non-metallic mineral manufactures, nes ; | AY1: 67 Iron and steel ; | AZ1: 68 Non-ferrous metals ; | BA1: 69 Manufactures of metals, nes ; | BB1: 7 Machinery and transport equipment ; | BC1: 71 Power generating machinery and equipment ; | BD1: 72 Machinery specialized for particular industries ; | BE1: 73 Metalworking machinery ; | BF1: 74 General industrial machinery and equipment, nes, and machine parts, nes ; | BG1: 75 Office machines and automatic data processing machines ; | BH1: 76 Telecommunications and sound recording and reproducing apparatus and equipment ; | BI1: 77 Electrical machinery, apparatus and appliances, nes, and electrical parts thereof (incl. non electrical counterparts, nes, of electrical household type equipment) ; | BJ1: 78 Road vehicles (incl. air-cushion vehicles) ; | BK1: 79 Transport equipment (excl. road vehicles) ; | BL1: 8 Miscellaneous manufactured articles ; | BM1: 81 Prefabricated buildings and sanitary, plumbing, heating and lighting fixtures and fittings, nes ; | BN1: 82 Furniture and parts thereof; bedding, mattresses, mattress supports, cushions and similar stuffed furnishings ; | BO1: 83 Travel goods, handbags and similar containers ; | BP1: 84 Articles of apparel and clothing accessories ; | BQ1: 85 Footwear ; | BR1: 87 Professional, scientific and controlling instruments and apparatus, nes ; | BS1: 88 Photographic apparatus, equipment and supplies and optical goods, nes; watches and clocks ; | BT1: 89 Miscellaneous manufactured articles, nes ; | BU1: 9 Commodities and transactions not classified elsewhere in the SITC ; | BV1: 91 Special transactions and commodities not classified according to kind ; | BW1: 92 Gold coin whether or not legal tender, and other coin being legal tender ; | BX1: 93 Coin (excl. gold coin) not being legal tender ; | BY1: 94 Gold, non-monetary (excl. gold ores and concentrates) ; | BZ1: 95 Combined confidential items excluding some of SITC 28099 (exports only) and some of SITC 51099 (imports only) ; | CA1: -1 TOTAL ;
A2: Unit | B2: $ Millions | C2: $ Millions | D2: $ Millions | E2: $ Millions | F2: $ Millions | G2: $ Millions | H2: $ Millions | I2: $ Millions | J2: $ Millions | K2: $ Millions | L2: $ Millions | M2: $ Millions | N2: $ Millions | O2: $ Millions | P2: $ Millions | Q2: $ Millions | R2: $ Millions | S2: $ Millions | T2: $ Millions | U2: $ Millions | V2: $ Millions | W2: $ Millions | X2: $ Millions | Y2: $ Millions | Z2: $ Millions | AA2: $ Millions | AB2: $ Millions | AC2: $ Millions | AD2: $ Millions | AE2: $ Millions | AF2: $ Millions | AG2: $ Millions | AH2: $ Millions | AI2: $ Millions | AJ2: $ Millions | AK2: $ Millions | AL2: $ Millions | AM2: $ Millions | AN2: $ Millions | AO2: $ Millions | AP2: $ Millions | AQ2: $ Millions | AR2: $ Millions | AS2: $ Millions | AT2: $ Millions | AU2: $ Millions | AV2: $ Millions | AW2: $ Millions | AX2: $ Millions | AY2: $ Millions | AZ2: $ Millions | BA2: $ Millions | BB2: $ Millions | BC2: $ Millions | BD2: $ Millions | BE2: $ Millions | BF2: $ Millions | BG2: $ Millions | BH2: $ Millions | BI2: $ Millions | BJ2: $ Millions | BK2: $ Millions | BL2: $ Millions | BM2: $ Millions | BN2: $ Millions | BO2: $ Millions | BP2: $ Millions | BQ2: $ Millions | BR2: $ Millions | BS2: $ Millions | BT2: $ Millions | BU2: $ Millions | BV2: $ Millions | BW2: $ Millions | BX2: $ Millions | BY2: $ Millions | BZ2: $ Millions | CA2: $ Millions
A3: Series ID | B3: A1828644C | C3: A1828645F | D3: A1828646J | E3: A1828647K | F3: A1828648L | G3: A1828649R | H3: A1828650X | I3: A1828651A | J3: A1828652C | K3: A1828653F | L3: A1828654J | M3: A1828655K | N3: A1828656L | O3: A1828657R | P3: A1828658T | Q3: A1828659V | R3: A1828660C | S3: A1828661F | T3: A1828662J | U3: A1828663K | V3: A1828664L | W3: A1828665R | X3: A1828666T | Y3: A1828667V | Z3: A1828668W | AA3: A1828669X | AB3: A1828670J | AC3: A1828671K | AD3: A1828672L | AE3: A1828673R | AF3: A1828674T | AG3: A1828675V | AH3: A1828676W | AI3: A1828677X | AJ3: A1828678A | AK3: A1828679C | AL3: A1828680L | AM3: A1828681R | AN3: A1828682T | AO3: A1828683V | AP3: A1828684W | AQ3: A1828685X | AR3: A1828686A | AS3: A1828687C | AT3: A1828688F | AU3: A1828689J | AV3: A1828690T | AW3: A1828691V | AX3: A1828692W | AY3: A1828693X | AZ3: A1828694A | BA3: A1828695C | BB3: A1828696F | BC3: A1828697J | BD3: A1828698K | BE3: A1828699L | BF3: A1828700K | BG3: A1828701L | BH3: A1828702R | BI3: A1828703T | BJ3: A1828704V | BK3: A1828705W | BL3: A1828706X | BM3: A1828707A | BN3: A1828708C | BO3: A1828709F | BP3: A1828710R | BQ3: A1828711T | BR3: A1828712V | BS3: A1828713W | BT3: A1828714X | BU3: A1828715A | BV3: A1828716C | BW3: A1828717F | BX3: A1828718J | BY3: A1828719K | BZ3: A1828720V | CA3: A1828721W
A4: Y1988 | B4: 1689 | C4: 154 | D4: 25 | E4: 90 | F4: 406 | G4: 69 | H4: 312 | I4: 37 | J4: 359 | K4: 60 | L4: 177 | M4: 367 | N4: 264 | O4: 103 | P4: 1518 | Q4: 13 | R4: 43 | S4: 111 | T4: 483 | U4: 232 | V4: 185 | W4: 266 | X4: 81 | Y4: 104 | Z4: 1699 | AA4: 3 | AB4: 1693 | AC4: 3 | AD4: 105 | AE4: 0 | AF4: 94 | AG4: 11 | AH4: 4644 | AI4: 1172 | AJ4: 594 | AK4: 200 | AL4: 687 | AM4: 270 | AN4: 171 | AO4: 597 | AP4: 421 | AQ4: 532 | AR4: 7271 | AS4: 150 | AT4: 621 | AU4: 214 | AV4: 1212 | AW4: 1911 | AX4: 885 | AY4: 892 | AZ4: 297 | BA4: 1089 | BB4: 17882 | BC4: 1123 | BD4: 2131 | BE4: 354 | BF4: 2326 | BG4: 2899 | BH4: 1543 | BI4: 2213 | BJ4: 3852 | BK4: 1441 | BL4: 5959 | BM4: 116 | BN4: 251 | BO4: 175 | BP4: 700 | BQ4: 304 | BR4: 993 | BS4: 763 | BT4: 2657 | BU4: 1285 | BV4: 935 | BW4: 17 | BX4: 0 | BY4: 104 | BZ4: 229 | CA4: 42419
A5: Y1989 | B5: 1928 | C5: 151 | D5: 30 | E5: 96 | F5: 441 | G5: 86 | H5: 418 | I5: 49 | J5: 357 | K5: 67 | L5: 233 | M5: 386 | N5: 298 | O5: 88 | P5: 1608 | Q5: 10 | R5: 33 | S5: 103 | T5: 571 | U5: 239 | V5: 159 | W5: 256 | X5: 118 | Y5: 119 | Z5: 2643 | AA5: 23 | AB5: 2612 | AC5: 8 | AD5: 120 | AE5: 1 | AF5: 107 | AG5: 12 | AH5: 5188 | AI5: 1123 | AJ5: 760 | AK5: 233 | AL5: 739 | AM5: 327 | AN5: 227 | AO5: 699 | AP5: 483 | AQ5: 597 | AR5: 8579 | AS5: 146 | AT5: 734 | AU5: 243 | AV5: 1342 | AW5: 2045 | AX5: 1078 | AY5: 1218 | AZ5: 414 | BA5: 1359 | BB5: 23456 | BC5: 1240 | BD5: 2752 | BE5: 388 | BF5: 2891 | BG5: 3531 | BH5: 1880 | BI5: 2621 | BJ5: 5397 | BK5: 2756 | BL5: 6813 | BM5: 140 | BN5: 339 | BO5: 215 | BP5: 848 | BQ5: 342 | BR5: 1138 | BS5: 806 | BT5: 2985 | BU5: 995 | BV5: 651 | BW5: 25 | BX5: 3 | BY5: 189 | BZ5: 127 | CA5: 51716
A6: Y1990 | B6: 1915 | C6: 121 | D6: 28 | E6: 115 | F6: 438 | G6: 101 | H6: 388 | I6: 61 | J6: 316 | K6: 69 | L6: 278 | M6: 403 | N6: 301 | O6: 102 | P6: 1405 | Q6: 14 | R6: 53 | S6: 83 | T6: 456 | U6: 207 | V6: 141 | W6: 186 | X6: 148 | Y6: 117 | Z6: 2806 | AA6: 3 | AB6: 2787 | AC6: 16 | AD6: 122 | AE6: 0 | AF6: 110 | AG6: 12 | AH6: 5129 | AI6: 984 | AJ6: 695 | AK6: 229 | AL6: 904 | AM6: 339 | AN6: 261 | AO6: 613 | AP6: 459 | AQ6: 645 | AR6: 7627 | AS6: 128 | AT6: 703 | AU6: 221 | AV6: 1255 | AW6: 1856 | AX6: 996 | AY6: 834 | AZ6: 373 | BA6: 1261 | BB6: 22381 | BC6: 1361 | BD6: 2446 | BE6: 354 | BF6: 2789 | BG6: 3462 | BH6: 1778 | BI6: 2615 | BJ6: 4825 | BK6: 2751 | BL6: 6918 | BM6: 139 | BN6: 314 | BO6: 209 | BP6: 914 | BQ6: 359 | BR6: 1155 | BS6: 786 | BT6: 3042 | BU6: 1092 | BV6: 493 | BW6: 28 | BX6: 7 | BY6: 427 | BZ6: 137 | CA6: 49798
A7: Y1991 | B7: 2009 | C7: 62 | D7: 40 | E7: 133 | F7: 453 | G7: 108 | H7: 433 | I7: 57 | J7: 310 | K7: 85 | L7: 328 | M7: 388 | N7: 286 | O7: 102 | P7: 1195 | Q7: 9 | R7: 58 | S7: 79 | T7: 437 | U7: 130 | V7: 134 | W7: 123 | X7: 115 | Y7: 110 | Z7: 2949 | AA7: 4 | AB7: 2938 | AC7: 7 | AD7: 137 | AE7: 0 | AF7: 124 | AG7: 13 | AH7: 5252 | AI7: 1044 | AJ7: 718 | AK7: 245 | AL7: 937 | AM7: 350 | AN7: 284 | AO7: 602 | AP7: 454 | AQ7: 618 | AR7: 7575 | AS7: 118 | AT7: 704 | AU7: 225 | AV7: 1209 | AW7: 1907 | AX7: 925 | AY7: 895 | AZ7: 371 | BA7: 1221 | BB7: 21886 | BC7: 1311 | BD7: 2023 | BE7: 315 | BF7: 2764 | BG7: 3406 | BH7: 1823 | BI7: 2645 | BJ7: 4280 | BK7: 3319 | BL7: 7281 | BM7: 154 | BN7: 301 | BO7: 221 | BP7: 1027 | BQ7: 384 | BR7: 1241 | BS7: 793 | BT7: 3160 | BU7: 998 | BV7: 28 | BW7: 11 | BX7: 0 | BY7: 866 | BZ7: 93 | CA7: 49670
A8: Y1992 | B8: 2148 | C8: 59 | D8: 39 | E8: 152 | F8: 483 | G8: 131 | H8: 475 | I8: 73 | J8: 328 | K8: 70 | L8: 338 | M8: 410 | N8: 303 | O8: 107 | P8: 1419 | Q8: 0 | R8: 58 | S8: 93 | T8: 516 | U8: 153 | V8: 142 | W8: 154 | X8: 170 | Y8: 133 | Z8: 3242 | AA8: 5 | AB8: 3222 | AC8: 15 | AD8: 174 | AE8: 0 | AF8: 156 | AG8: 18 | AH8: 6220 | AI8: 1284 | AJ8: 700 | AK8: 305 | AL8: 1275 | AM8: 438 | AN8: 310 | AO8: 650 | AP8: 531 | AQ8: 727 | AR8: 8433 | AS8: 132 | AT8: 781 | AU8: 245 | AV8: 1387 | AW8: 2090 | AX8: 1024 | AY8: 856 | AZ8: 440 | BA8: 1478 | BB8: 23732 | BC8: 1345 | BD8: 2350 | BE8: 314 | BF8: 2892 | BG8: 3949 | BH8: 2188 | BI8: 3093 | BJ8: 5576 | BK8: 2025 | BL8: 8515 | BM8: 166 | BN8: 342 | BO8: 273 | BP8: 1208 | BQ8: 481 | BR8: 1444 | BS8: 931 | BT8: 3670 | BU8: 1198 | BV8: 27 | BW8: 1 | BX8: 0 | BY8: 1104 | BZ8: 66 | CA8: 55491
A9: Y1993 | B9: 2381 | C9: 65 | D9: 39 | E9: 159 | F9: 538 | G9: 139 | H9: 501 | I9: 73 | J9: 358 | K9: 87 | L9: 422 | M9: 451 | N9: 318 | O9: 133 | P9: 1548 | Q9: 4 | R9: 65 | S9: 111 | T9: 652 | U9: 141 | V9: 153 | W9: 139 | X9: 128 | Y9: 155 | Z9: 3819 | AA9: 16 | AB9: 3781 | AC9: 22 | AD9: 196 | AE9: 0 | AF9: 179 | AG9: 17 | AH9: 6843 | AI9: 1491 | AJ9: 582 | AK9: 335 | AL9: 1393 | AM9: 491 | AN9: 376 | AO9: 728 | AP9: 606 | AQ9: 841 | AR9: 9137 | AS9: 137 | AT9: 883 | AU9: 274 | AV9: 1485 | AW9: 2208 | AX9: 1038 | AY9: 1038 | AZ9: 476 | BA9: 1598 | BB9: 27486 | BC9: 1665 | BD9: 2717 | BE9: 324 | BF9: 3425 | BG9: 4576 | BH9: 2488 | BI9: 3752 | BJ9: 6695 | BK9: 1844 | BL9: 9421 | BM9: 182 | BN9: 369 | BO9: 272 | BP9: 1454 | BQ9: 515 | BR9: 1648 | BS9: 1024 | BT9: 3957 | BU9: 1109 | BV9: 37 | BW9: 1 | BX9: 0 | BY9: 1003 | BZ9: 68 | CA9: 62391
A10: Y1994 | B10: 2583 | C10: 81 | D10: 42 | E10: 161 | F10: 582 | G10: 148 | H10: 504 | I10: 75 | J10: 437 | K10: 107 | L10: 446 | M10: 501 | N10: 338 | O10: 163 | P10: 1650 | Q10: 4 | R10: 105 | S10: 128 | T10: 605 | U10: 131 | V10: 174 | W10: 163 | X10: 169 | Y10: 171 | Z10: 3264 | AA10: 26 | AB10: 3212 | AC10: 26 | AD10: 209 | AE10: 2 | AF10: 187 | AG10: 20 | AH10: 7359 | AI10: 1706 | AJ10: 462 | AK10: 355 | AL10: 1504 | AM10: 547 | AN10: 443 | AO10: 804 | AP10: 666 | AQ10: 872 | AR10: 10019 | AS10: 156 | AT10: 998 | AU10: 305 | AV10: 1639 | AW10: 2368 | AX10: 1144 | AY10: 1101 | AZ10: 588 | BA10: 1720 | BB10: 31427 | BC10: 1759 | BD10: 3341 | BE10: 436 | BF10: 3912 | BG10: 5201 | BH10: 2874 | BI10: 4375 | BJ10: 7963 | BK10: 1566 | BL10: 10229 | BM10: 206 | BN10: 425 | BO10: 314 | BP10: 1547 | BQ10: 557 | BR10: 1762 | BS10: 1140 | BT10: 4278 | BU10: 861 | BV10: 25 | BW10: 1 | BX10: 0 | BY10: 773 | BZ10: 62 | CA10: 68102
A11: Y1995 | B11: 2947 | C11: 106 | D11: 51 | E11: 185 | F11: 598 | G11: 218 | H11: 575 | I11: 88 | J11: 525 | K11: 104 | L11: 497 | M11: 504 | N11: 341 | O11: 163 | P11: 1746 | Q11: 1 | R11: 131 | S11: 166 | T11: 522 | U11: 205 | V11: 182 | W11: 157 | X11: 182 | Y11: 200 | Z11: 3887 | AA11: 14 | AB11: 3823 | AC11: 50 | AD11: 251 | AE11: 2 | AF11: 226 | AG11: 23 | AH11: 8599 | AI11: 1862 | AJ11: 797 | AK11: 370 | AL11: 1691 | AM11: 598 | AN11: 584 | AO11: 980 | AP11: 774 | AQ11: 943 | AR11: 11353 | AS11: 168 | AT11: 1084 | AU11: 327 | AV11: 2048 | AW11: 2416 | AX11: 1211 | AY11: 1459 | AZ11: 689 | BA11: 1951 | BB11: 36393 | BC11: 1845 | BD11: 3914 | BE11: 558 | BF11: 4379 | BG11: 5969 | BH11: 3684 | BI11: 5298 | BJ11: 8433 | BK11: 2313 | BL11: 10963 | BM11: 218 | BN11: 457 | BO11: 359 | BP11: 1703 | BQ11: 568 | BR11: 1887 | BS11: 1230 | BT11: 4541 | BU11: 827 | BV11: 27 | BW11: 1 | BX11: 0 | BY11: 731 | BZ11: 68 | CA11: 77470
A12: Y1996 | B12: 2919 | C12: 92 | D12: 56 | E12: 201 | F12: 605 | G12: 165 | H12: 597 | I12: 87 | J12: 484 | K12: 105 | L12: 527 | M12: 511 | N12: 341 | O12: 170 | P12: 1503 | Q12: 0 | R12: 100 | S12: 144 | T12: 419 | U12: 155 | V12: 166 | W12: 131 | X12: 171 | Y12: 217 | Z12: 4898 | AA12: 15 | AB12: 4800 | AC12: 83 | AD12: 263 | AE12: 4 | AF12: 236 | AG12: 23 | AH12: 9078 | AI12: 2007 | AJ12: 795 | AK12: 404 | AL12: 1937 | AM12: 623 | AN12: 746 | AO12: 869 | AP12: 719 | AQ12: 978 | AR12: 10610 | AS12: 159 | AT12: 1119 | AU12: 319 | AV12: 1770 | AW12: 2319 | AX12: 1208 | AY12: 1264 | AZ12: 601 | BA12: 1851 | BB12: 36813 | BC12: 2037 | BD12: 4107 | BE12: 606 | BF12: 4567 | BG12: 5882 | BH12: 3724 | BI12: 5100 | BJ12: 8243 | BK12: 2547 | BL12: 11055 | BM12: 225 | BN12: 495 | BO12: 343 | BP12: 1802 | BQ12: 610 | BR12: 1892 | BS12: 1241 | BT12: 4447 | BU12: 751 | BV12: 31 | BW12: 9 | BX12: 0 | BY12: 643 | BZ12: 68 | CA12: 78401
A13: Y1997 | B13: 3192 | C13: 120 | D13: 69 | E13: 193 | F13: 631 | G13: 204 | H13: 590 | I13: 90 | J13: 582 | K13: 134 | L13: 579 | M13: 544 | N13: 401 | O13: 143 | P13: 1562 | Q13: 1 | R13: 91 | S13: 130 | T13: 462 | U13: 124 | V13: 149 | W13: 165 | X13: 199 | Y13: 241 | Z13: 5023 | AA13: 13 | AB13: 4916 | AC13: 94 | AD13: 270 | AE13: 9 | AF13: 240 | AG13: 21 | AH13: 9400 | AI13: 2070 | AJ13: 634 | AK13: 425 | AL13: 2215 | AM13: 676 | AN13: 661 | AO13: 926 | AP13: 754 | AQ13: 1039 | AR13: 11533 | AS13: 159 | AT13: 1143 | AU13: 368 | AV13: 1833 | AW13: 2385 | AX13: 1336 | AY13: 1466 | AZ13: 692 | BA13: 2151 | BB13: 38694 | BC13: 1952 | BD13: 4032 | BE13: 596 | BF13: 5040 | BG13: 6496 | BH13: 3764 | BI13: 5085 | BJ13: 9590 | BK13: 2139 | BL13: 12286 | BM13: 258 | BN13: 613 | BO13: 358 | BP13: 2049 | BQ13: 658 | BR13: 2138 | BS13: 1315 | BT13: 4897 | BU13: 917 | BV13: 37 | BW13: 9 | BX13: 0 | BY13: 796 | BZ13: 75 | CA13: 83421
A14: Y1998 | B14: 3663 | C14: 120 | D14: 59 | E14: 239 | F14: 729 | G14: 230 | H14: 666 | I14: 104 | J14: 678 | K14: 155 | L14: 683 | M14: 589 | N14: 434 | O14: 155 | P14: 1624 | Q14: 0 | R14: 64 | S14: 118 | T14: 480 | U14: 173 | V14: 139 | W14: 191 | X14: 200 | Y14: 259 | Z14: 4323 | AA14: 28 | AB14: 4223 | AC14: 72 | AD14: 268 | AE14: 6 | AF14: 238 | AG14: 24 | AH14: 11037 | AI14: 2265 | AJ14: 779 | AK14: 472 | AL14: 2843 | AM14: 825 | AN14: 775 | AO14: 1010 | AP14: 871 | AQ14: 1197 | AR14: 13019 | AS14: 137 | AT14: 1318 | AU14: 419 | AV14: 2092 | AW14: 2600 | AX14: 1555 | AY14: 1609 | AZ14: 874 | BA14: 2415 | BB14: 44333 | BC14: 2163 | BD14: 4455 | BE14: 531 | BF14: 5855 | BG14: 7089 | BH14: 4140 | BI14: 5716 | BJ14: 11724 | BK14: 2660 | BL14: 14555 | BM14: 309 | BN14: 751 | BO14: 360 | BP14: 2419 | BQ14: 780 | BR14: 2457 | BS14: 1421 | BT14: 6058 | BU14: 3369 | BV14: 43 | BW14: 4 | BX14: 0 | BY14: 3174 | BZ14: 148 | CA14: 96780
A15: Y1999 | B15: 3844 | C15: 125 | D15: 98 | E15: 274 | F15: 779 | G15: 253 | H15: 742 | I15: 106 | J15: 630 | K15: 144 | L15: 693 | M15: 672 | N15: 496 | O15: 176 | P15: 1621 | Q15: 0 | R15: 68 | S15: 104 | T15: 486 | U15: 203 | V15: 139 | W15: 157 | X15: 182 | Y15: 282 | Z15: 5909 | AA15: 26 | AB15: 5797 | AC15: 86 | AD15: 284 | AE15: 6 | AF15: 244 | AG15: 34 | AH15: 11762 | AI15: 2557 | AJ15: 660 | AK15: 500 | AL15: 3212 | AM15: 884 | AN15: 746 | AO15: 1041 | AP15: 901 | AQ15: 1261 | AR15: 12934 | AS15: 159 | AT15: 1231 | AU15: 510 | AV15: 2186 | AW15: 2579 | AX15: 1678 | AY15: 1413 | AZ15: 794 | BA15: 2384 | BB15: 47801 | BC15: 2363 | BD15: 4063 | BE15: 436 | BF15: 5355 | BG15: 7199 | BH15: 5907 | BI15: 5897 | BJ15: 12373 | BK15: 4208 | BL15: 14513 | BM15: 325 | BN15: 893 | BO15: 382 | BP15: 2573 | BQ15: 782 | BR15: 2494 | BS15: 1447 | BT15: 5617 | BU15: 2166 | BV15: 37 | BW15: 7 | BX15: 5 | BY15: 2005 | BZ15: 112 | CA15: 101506
... A39: Y2023 | B39: 19679 | C39: 212 | D39: 1035 | E39: 2034 | F39: 2230 | G39: 2137 | H39: 3365 | I39: 611 | J39: 2582 | K39: 1438 | L39: 4035 | M39: 3516 | N39: 2928 | O39: 588 | P39: 3930 | Q39: 2 | R39: 120 | S39: 130 | T39: 841 | U39: 280 | V39: 119 | W39: 478 | X39: 1019 | Y39: 941 | Z39: 60980 | AA39: 306 | AB39: 60381 | AC39: 293 | AD39: 991 | AE39: 162 | AF39: 751 | AG39: 78 | AH39: 42832 | AI39: 2720 | AJ39: 2830 | AK39: 1148 | AL39: 17001 | AM39: 5168 | AN39: 3563 | AO39: 2728 | AP39: 2702 | AQ39: 4972 | AR39: 40646 | AS39: 176 | AT39: 5190 | AU39: 1733 | AV39: 3827 | AW39: 4277 | AX39: 4605 | AY39: 4746 | AZ39: 4174 | BA39: 11918 | BB39: 173529 | BC39: 7399 | BD39: 18320 | BE39: 1171 | BF39: 20855 | BG39: 12526 | BH39: 20205 | BI39: 23991 | BJ39: 63067 | BK39: 5995 | BL39: 55706 | BM39: 1960 | BN39: 5336 | BO39: 2249 | BP39: 12165 | BQ39: 2886 | BR39: 10011 | BS39: 2601 | BT39: 18498 | BU39: 12573 | BV39: 6 | BW39: 66 | BX39: 19 | BY39: 8565 | BZ39: 3917 | CA39: 414382

Sheet Export_Statistical
A1: Export | B1: 0 Food and live animals ; | C1: 00 Live animals (excl. fish (not marine mammals) crustaceans, molluscs and aquatic invertebrates of SITC Division 03) ; | D1: 01 Meat and meat preparations ; | E1: 02 Dairy products and birds’ eggs ; | F1: 03 Fish (excl. marine mammals) crustaceans, molluscs and aquatic invertebrates, and preparations thereof (excl. extracts and juices of fish, crustaceans, molluscs or other aquatic invertebrates, prepared or preserved of SITC 01710) ; | G1: 04 Cereals and cereal preparations ; | H1: 05 Vegetables and fruit ; | I1: 06 Sugars, sugar preparations and honey ; | J1: 07 Coffee, tea, cocoa, spices, and manufactures thereof ; | K1: 08 Feeding stuff for animals (excl. unmilled cereals) ; | L1: 09 Miscellaneous edible products and preparations ; | M1: 1 Beverages and tobacco ; | N1: 11 Beverages ; | O1: 12 Tobacco and tobacco manufactures ; | P1: 2 Crude materials, inedible, except fuels ; | Q1: 21 Hides, skins and furskins, raw ; | R1: 22 Oil-seeds and oleaginous fruits ; | S1: 23 Crude rubber (incl. synthetic and reclaimed) ; | T1: 24 Cork and wood ; | U1: 25 Pulp and waste paper ; | V1: 26 Textile fibres (excl. wool tops and other combed wool) and their wastes, not manufactured into yarn or fabric ; | W1: 27 Crude fertilizers (excl. those of Division 56) and crude minerals (excl. coal, petroleum and precious stones) ; | X1: 28 Metalliferous ores and metal scrap ; | Y1: 29 Crude animal and vegetable materials, nes ; | Z1: 3 Mineral fuels, lubricants and related materials ; | AA1: 31 Coal, coke and briquettes ; | AB1: 32 Petroleum, petroleum products and related materials ; | AC1: 33 Gas, natural and manufactured ; | AD1: 4 Animal and vegetable oils, fats and waxes ; | AE1: 41 Animal oils and fats ; | AF1: 42 Fixed vegetable fats and oils, crude, refined or fractionated ; | AG1: 43 Animal or vegetable fats and oils, processed; waxes of animal or vegetable origin; inedible mixtures or preparations of animal or vegetable fats or oils, nes ; | AH1: 5 Chemicals and related products, nes ; | AI1: 51 Organic chemicals ; | AJ1: 52 Inorganic chemicals ; | AK1: 53 Dyeing, tanning and colouring materials ; | AL1: 54 Medicinal and pharmaceutical products ; | AM1: 55 Essential oils and resinoids and perfume materials; toilet, polishing and cleansing preparations ; | AN1: 56 Fertilisers (excl. those of group 272) ; | AO1: 57 Plastics in primary forms ; | AP1: 58 Plastics in non-primary forms ; | AQ1: 59 Chemical materials and products, nes ; | AR1: 6 Manufactured goods classified chiefly by material ; | AS1: 61 Leather, leather manufactures, nes, and dressed furskins ; | AT1: 62 Rubber manufactures, nes ; | AU1: 63 Cork and wood manufactures (excl. furniture) ; | AV1: 64 Paper, paperboard and articles of paper pulp, of paper or of paperboard ; | AW1: 65 Textile yarn, fabrics, made-up articles nes, and related products ; | AX1: 66 Non-metallic mineral manufactures, nes ; | AY1: 67 Iron and steel ; | AZ1: 68 Non-ferrous metals ; | BA1: 69 Manufactures of metals, nes ; | BB1: 7 Machinery and transport equipment ; | BC1: 71 Power generating machinery and equipment ; | BD1: 72 Machinery specialized for particular industries ; | BE1: 73 Metalworking machinery ; | BF1: 74 General industrial machinery and equipment, nes, and machine parts, nes ; | BG1: 75 Office machines and automatic data processing machines ; | BH1: 76 Telecommunications and sound recording and reproducing apparatus and equipment ; | BI1: 77 Electrical machinery, apparatus and appliances, nes, and electrical parts thereof (incl. non electrical counterparts, nes, of electrical household type equipment) ; | BJ1: 78 Road vehicles (incl. air-cushion vehicles) ; | BK1: 79 Transport equipment (excl. road vehicles) ; | BL1: 8 Miscellaneous manufactured articles ; | BM1: 81 Prefabricated buildings and sanitary, plumbing, heating and lighting fixtures and fittings, nes ; | BN1: 82 Furniture and parts thereof; bedding, mattresses, mattress supports, cushions and similar stuffed furnishings ; | BO1: 83 Travel goods, handbags and similar containers ; | BP1: 84 Articles of apparel and clothing accessories ; | BQ1: 85 Footwear ; | BR1: 87 Professional, scientific and controlling instruments and apparatus, nes ; | BS1: 88 Photographic apparatus, equipment and supplies and optical goods, nes; watches and clocks ; | BT1: 89 Miscellaneous manufactured articles, nes ; | BU1: 9 Commodities and transactions not classified elsewhere in the SITC ; | BV1: 91 Special transactions and commodities not classified according to kind ; | BW1: 92 Gold coin whether or not legal tender, and other coin being legal tender ; | BX1: 93 Coin (excl. gold coin) not being legal tender ; | BY1: 94 Gold, non-monetary (excl. gold ores and concentrates) ; | BZ1: 95 Combined confidential items excluding some of SITC 28099 (exports only) and some of SITC 51099 (imports only) ; | CA1: -1 TOTAL ;
A2: Unit | B2: $ Millions | C2: $ Millions | D2: $ Millions | E2: $ Millions | F2: $ Millions | G2: $ Millions | H2: $ Millions | I2: $ Millions | J2: $ Millions | K2: $ Millions | L2: $ Millions | M2: $ Millions | N2: $ Millions | O2: $ Millions | P2: $ Millions | Q2: $ Millions | R2: $ Millions | S2: $ Millions | T2: $ Millions | U2: $ Millions | V2: $ Millions | W2: $ Millions | X2: $ Millions | Y2: $ Millions | Z2: $ Millions | AA2: $ Millions | AB2: $ Millions | AC2: $ Millions | AD2: $ Millions | AE2: $ Millions | AF2: $ Millions | AG2: $ Millions | AH2: $ Millions | AI2: $ Millions | AJ2: $ Millions | AK2: $ Millions | AL2: $ Millions | AM2: $ Millions | AN2: $ Millions | AO2: $ Millions | AP2: $ Millions | AQ2: $ Millions | AR2: $ Millions | AS2: $ Millions | AT2: $ Millions | AU2: $ Millions | AV2: $ Millions | AW2: $ Millions | AX2: $ Millions | AY2: $ Millions | AZ2: $ Millions | BA2: $ Millions | BB2: $ Millions | BC2: $ Millions | BD2: $ Millions | BE2: $ Millions | BF2: $ Millions | BG2: $ Millions | BH2: $ Millions | BI2: $ Millions | BJ2: $ Millions | BK2: $ Millions | BL2: $ Millions | BM2: $ Millions | BN2: $ Millions | BO2: $ Millions | BP2: $ Millions | BQ2: $ Millions | BR2: $ Millions | BS2: $ Millions | BT2: $ Millions | BU2: $ Millions | BV2: $ Millions | BW2: $ Millions | BX2: $ Millions | BY2: $ Millions | BZ2: $ Millions | CA2: $ Millions
A3: Series ID | B3: A1827804K | C3: A1827805L | D3: A1827806R | E3: A1827807T | F3: A1827808V | G3: A1827809W | H3: A1827810F | I3: A1827811J | J3: A1827812K | K3: A1827813L | L3: A1827814R | M3: A1827815T | N3: A1827816V | O3: A1827817W | P3: A1827818X | Q3: A1827819A | R3: A1827820K | S3: A1827821L | T3: A1827822R | U3: A1827823T | V3: A1827824V | W3: A1827825W | X3: A1827826X | Y3: A1827827A | Z3: A1827828C | AA3: A1827829F | AB3: A1827830R | AC3: A1827831T | AD3: A1827832V | AE3: A1827833W | AF3: A1827834X | AG3: A1827835A | AH3: A1827836C | AI3: A1827837F | AJ3: A1827838J | AK3: A1827839K | AL3: A1827840V | AM3: A1827841W | AN3: A1827842X | AO3: A1827843A | AP3: A1827844C | AQ3: A1827845F | AR3: A1827846J | AS3: A1827847K | AT3: A1827848L | AU3: A1827849R | AV3: A1827850X | AW3: A1827851A | AX3: A1827852C | AY3: A1827853F | AZ3: A1827854J | BA3: A1827855K | BB3: A1827856L | BC3: A1827857R | BD3: A1827858T | BE3: A1827859V | BF3: A1827860C | BG3: A1827861F | BH3: A1827862J | BI3: A1827863K | BJ3: A1827864L | BK3: A1827865R | BL3: A1827866T | BM3: A1827867V | BN3: A1827868W | BO3: A1827869X | BP3: A1827870J | BQ3: A1827871K | BR3: A1827872L | BS3: A1827873R | BT3: A1827874T | BU3: A1827875V | BV3: A1827876W | BW3: A1827877X | BX3: A1827878A | BY3: A1827879C | BZ3: A1827880L | CA3: A1827881R
A4: Y1988 | B4: 7903 | C4: 322 | D4: 2423 | E4: 529 | F4: 663 | G4: 2071 | H4: 604 | I4: 859 | J4: 68 | K4: 273 | L4: 91 | M4: 272 | N4: 250 | O4: 22 | P4: 13373 | Q4: 614 | R4: 63 | S4: 10 | T4: 439 | U4: 37 | V4: 6270 | W4: 221 | X4: 5595 | Y4: 124 | Z4: 6461 | AA4: 4636 | AB4: 1615 | AC4: 210 | AD4: 146 | AE4: 122 | AF4: 14 | AG4: 10 | AH4: 1041 | AI4: 102 | AJ4: 86 | AK4: 109 | AL4: 229 | AM4: 89 | AN4: 9 | AO4: 157 | AP4: 61 | AQ4: 199 | AR4: 5344 | AS4: 165 | AT4: 72 | AU4: 15 | AV4: 116 | AW4: 148 | AX4: 318 | AY4: 501 | AZ4: 3703 | BA4: 306 | BB4: 2744 | BC4: 366 | BD4: 336 | BE4: 39 | BF4: 322 | BG4: 406 | BH4: 142 | BI4: 280 | BJ4: 392 | BK4: 461 | BL4: 1075 | BM4: 31 | BN4: 36 | BO4: 2 | BP4: 65 | BQ4: 14 | BR4: 196 | BS4: 277 | BT4: 454 | BU4: 4006 | BV4: 156 | BW4: 196 | BX4: 1 | BY4: 2674 | BZ4: 979 | CA4: 42365
A5: Y1989 | B5: 9487 | C5: 244 | D5: 2639 | E5: 682 | F5: 646 | G5: 3205 | H5: 514 | I5: 1128 | J5: 65 | K5: 267 | L5: 97 | M5: 228 | N5: 211 | O5: 17 | P5: 14124 | Q5: 515 | R5: 44 | S5: 14 | T5: 409 | U5: 33 | V5: 5642 | W5: 206 | X5: 7128 | Y5: 133 | Z5: 7234 | AA5: 5314 | AB5: 1660 | AC5: 260 | AD5: 111 | AE5: 100 | AF5: 1 | AG5: 10 | AH5: 1174 | AI5: 90 | AJ5: 117 | AK5: 236 | AL5: 246 | AM5: 92 | AN5: 9 | AO5: 145 | AP5: 57 | AQ5: 182 | AR5: 6063 | AS5: 151 | AT5: 62 | AU5: 13 | AV5: 137 | AW5: 168 | AX5: 447 | AY5: 584 | AZ5: 4153 | BA5: 348 | BB5: 3286 | BC5: 378 | BD5: 382 | BE5: 54 | BF5: 351 | BG5: 480 | BH5: 219 | BI5: 327 | BJ5: 508 | BK5: 587 | BL5: 1257 | BM5: 28 | BN5: 35 | BO5: 3 | BP5: 88 | BQ5: 23 | BR5: 241 | BS5: 250 | BT5: 589 | BU5: 4035 | BV5: 153 | BW5: 205 | BX5: 0 | BY5: 2590 | BZ5: 1087 | CA5: 46999
A6: Y1990 | B6: 9726 | C6: 163 | D6: 3090 | E6: 676 | F6: 676 | G6: 3014 | H6: 581 | I6: 1101 | J6: 82 | K6: 238 | L6: 105 | M6: 285 | N6: 266 | O6: 19 | P6: 13461 | Q6: 528 | R6: 51 | S6: 8 | T6: 402 | U6: 21 | V6: 3939 | W6: 240 | X6: 8113 | Y6: 159 | Z6: 9596 | AA6: 6024 | AB6: 2882 | AC6: 690 | AD6: 126 | AE6: 113 | AF6: 1 | AG6: 12 | AH6: 1295 | AI6: 106 | AJ6: 175 | AK6: 221 | AL6: 293 | AM6: 105 | AN6: 12 | AO6: 136 | AP6: 76 | AQ6: 171 | AR6: 6257 | AS6: 180 | AT6: 67 | AU6: 33 | AV6: 168 | AW6: 196 | AX6: 464 | AY6: 909 | AZ6: 3833 | BA6: 407 | BB6: 4117 | BC6: 490 | BD6: 459 | BE6: 80 | BF6: 430 | BG6: 635 | BH6: 291 | BI6: 413 | BJ6: 736 | BK6: 583 | BL6: 1306 | BM6: 37 | BN6: 42 | BO6: 5 | BP6: 125 | BQ6: 22 | BR6: 252 | BS6: 241 | BT6: 582 | BU6: 4723 | BV6: 186 | BW6: 250 | BX6: 2 | BY6: 3440 | BZ6: 845 | CA6: 50892
A7: Y1991 | B7: 9311 | C7: 182 | D7: 3239 | E7: 793 | F7: 739 | G7: 2411 | H7: 651 | I7: 765 | J7: 92 | K7: 304 | L7: 135 | M7: 334 | N7: 313 | O7: 21 | P7: 13673 | Q7: 346 | R7: 59 | S7: 8 | T7: 461 | U7: 20 | V7: 4371 | W7: 290 | X7: 7955 | Y7: 163 | Z7: 10877 | AA7: 6857 | AB7: 2915 | AC7: 1105 | AD7: 136 | AE7: 117 | AF7: 1 | AG7: 18 | AH7: 1531 | AI7: 106 | AJ7: 253 | AK7: 188 | AL7: 381 | AM7: 125 | AN7: 17 | AO7: 181 | AP7: 82 | AQ7: 198 | AR7: 6484 | AS7: 187 | AT7: 67 | AU7: 50 | AV7: 209 | AW7: 218 | AX7: 556 | AY7: 1027 | AZ7: 3621 | BA7: 549 | BB7: 4862 | BC7: 566 | BD7: 523 | BE7: 79 | BF7: 511 | BG7: 808 | BH7: 317 | BI7: 542 | BJ7: 820 | BK7: 696 | BL7: 1423 | BM7: 38 | BN7: 36 | BO7: 2 | BP7: 142 | BQ7: 30 | BR7: 311 | BS7: 260 | BT7: 604 | BU7: 5074 | BV7: 197 | BW7: 321 | BX7: 0 | BY7: 3702 | BZ7: 854 | CA7: 53705
A8: Y1992 | B8: 10585 | C8: 226 | D8: 3669 | E8: 957 | F8: 913 | G8: 2449 | H8: 825 | I8: 888 | J8: 112 | K8: 405 | L8: 141 | M8: 377 | N8: 355 | O8: 22 | P8: 13497 | Q8: 398 | R8: 61 | S8: 11 | T8: 419 | U8: 9 | V8: 4539 | W8: 328 | X8: 7539 | Y8: 193 | Z8: 11612 | AA8: 7345 | AB8: 3123 | AC8: 1144 | AD8: 154 | AE8: 131 | AF8: 1 | AG8: 22 | AH8: 1817 | AI8: 77 | AJ8: 195 | AK8: 297 | AL8: 517 | AM8: 155 | AN8: 15 | AO8: 192 | AP8: 94 | AQ8: 275 | AR8: 7078 | AS8: 259 | AT8: 98 | AU8: 61 | AV8: 247 | AW8: 268 | AX8: 603 | AY8: 1179 | AZ8: 3816 | BA8: 547 | BB8: 5721 | BC8: 614 | BD8: 629 | BE8: 95 | BF8: 618 | BG8: 904 | BH8: 401 | BI8: 656 | BJ8: 887 | BK8: 917 | BL8: 1772 | BM8: 91 | BN8: 45 | BO8: 4 | BP8: 175 | BQ8: 36 | BR8: 367 | BS8: 338 | BT8: 716 | BU8: 5759 | BV8: 203 | BW8: 289 | BX8: 0 | BY8: 4476 | BZ8: 791 | CA8: 58372
A9: Y1993 | B9: 12435 | C9: 289 | D9: 3958 | E9: 1169 | F9: 1058 | G9: 3102 | H9: 912 | I9: 1210 | J9: 146 | K9: 430 | L9: 161 | M9: 492 | N9: 457 | O9: 35 | P9: 12753 | Q9: 378 | R9: 84 | S9: 10 | T9: 531 | U9: 13 | V9: 3662 | W9: 370 | X9: 7499 | Y9: 206 | Z9: 11983 | AA9: 7798 | AB9: 2964 | AC9: 1221 | AD9: 209 | AE9: 173 | AF9: 2 | AG9: 34 | AH9: 2189 | AI9: 83 | AJ9: 221 | AK9: 354 | AL9: 639 | AM9: 191 | AN9: 14 | AO9: 211 | AP9: 111 | AQ9: 365 | AR9: 7575 | AS9: 327 | AT9: 117 | AU9: 88 | AV9: 253 | AW9: 355 | AX9: 580 | AY9: 1380 | AZ9: 3895 | BA9: 580 | BB9: 7020 | BC9: 624 | BD9: 801 | BE9: 97 | BF9: 817 | BG9: 1169 | BH9: 436 | BI9: 886 | BJ9: 1096 | BK9: 1094 | BL9: 2000 | BM9: 46 | BN9: 75 | BO9: 10 | BP9: 222 | BQ9: 52 | BR9: 388 | BS9: 445 | BT9: 762 | BU9: 6093 | BV9: 295 | BW9: 222 | BX9: 0 | BY9: 4683 | BZ9: 893 | CA9: 62749
A10: Y1994 | B10: 13394 | C10: 359 | D10: 3799 | E10: 1423 | F10: 1092 | G10: 3340 | H10: 926 | I10: 1672 | J10: 173 | K10: 403 | L10: 207 | M10: 531 | N10: 493 | O10: 38 | P10: 13074 | Q10: 452 | R10: 128 | S10: 12 | T10: 531 | U10: 27 | V10: 4287 | W10: 352 | X10: 7074 | Y10: 211 | Z10: 10671 | AA10: 6750 | AB10: 2705 | AC10: 1216 | AD10: 223 | AE10: 184 | AF10: 7 | AG10: 32 | AH10: 2467 | AI10: 85 | AJ10: 277 | AK10: 372 | AL10: 729 | AM10: 235 | AN10: 23 | AO10: 209 | AP10: 123 | AQ10: 414 | AR10: 8280 | AS10: 426 | AT10: 126 | AU10: 89 | AV10: 253 | AW10: 417 | AX10: 787 | AY10: 1505 | AZ10: 3994 | BA10: 683 | BB10: 7606 | BC10: 602 | BD10: 806 | BE10: 120 | BF10: 935 | BG10: 1509 | BH10: 689 | BI10: 1088 | BJ10: 1014 | BK10: 843 | BL10: 2235 | BM10: 48 | BN10: 75 | BO10: 13 | BP10: 288 | BQ10: 56 | BR10: 444 | BS10: 483 | BT10: 828 | BU10: 6281 | BV10: 381 | BW10: 246 | BX10: 0 | BY10: 4671 | BZ10: 983 | CA10: 64762
A11: Y1995 | B11: 13073 | C11: 576 | D11: 3539 | E11: 1495 | F11: 1160 | G11: 2689 | H11: 921 | I11: 1877 | J11: 181 | K11: 412 | L11: 223 | M11: 585 | N11: 542 | O11: 43 | P11: 14647 | Q11: 492 | R11: 122 | S11: 13 | T11: 647 | U11: 47 | V11: 4404 | W11: 427 | X11: 8270 | Y11: 225 | Z11: 11980 | AA11: 7433 | AB11: 3029 | AC11: 1518 | AD11: 256 | AE11: 216 | AF11: 2 | AG11: 38 | AH11: 2908 | AI11: 80 | AJ11: 356 | AK11: 425 | AL11: 834 | AM11: 279 | AN11: 29 | AO11: 340 | AP11: 159 | AQ11: 406 | AR11: 9791 | AS11: 504 | AT11: 151 | AU11: 103 | AV11: 280 | AW11: 518 | AX11: 680 | AY11: 1767 | AZ11: 5094 | BA11: 694 | BB11: 9164 | BC11: 799 | BD11: 1063 | BE11: 142 | BF11: 1015 | BG11: 1753 | BH11: 689 | BI11: 1359 | BJ11: 1126 | BK11: 1218 | BL11: 2496 | BM11: 65 | BN11: 86 | BO11: 12 | BP11: 302 | BQ11: 63 | BR11: 469 | BS11: 530 | BT11: 969 | BU11: 6785 | BV11: 424 | BW11: 163 | BX11: 0 | BY11: 5263 | BZ11: 935 | CA11: 71685
A12: Y1996 | B12: 15804 | C12: 659 | D12: 2892 | E12: 1760 | F12: 1050 | G12: 5761 | H12: 1084 | I12: 1649 | J12: 196 | K12: 500 | L12: 253 | M12: 740 | N12: 677 | O12: 63 | P12: 15023 | Q12: 496 | R12: 218 | S12: 12 | T12: 621 | U12: 14 | V12: 4285 | W12: 384 | X12: 8771 | Y12: 222 | Z12: 13002 | AA12: 7818 | AB12: 3508 | AC12: 1676 | AD12: 237 | AE12: 194 | AF12: 10 | AG12: 33 | AH12: 3001 | AI12: 91 | AJ12: 333 | AK12: 420 | AL12: 942 | AM12: 300 | AN12: 23 | AO12: 299 | AP12: 153 | AQ12: 440 | AR12: 9429 | AS12: 471 | AT12: 159 | AU12: 109 | AV12: 343 | AW12: 566 | AX12: 770 | AY12: 1623 | AZ12: 4619 | BA12: 769 | BB12: 9955 | BC12: 878 | BD12: 1089 | BE12: 200 | BF12: 1219 | BG12: 1781 | BH12: 655 | BI12: 1347 | BJ12: 1538 | BK12: 1248 | BL12: 2813 | BM12: 85 | BN12: 99 | BO12: 14 | BP12: 339 | BQ12: 64 | BR12: 596 | BS12: 578 | BT12: 1038 | BU12: 6987 | BV12: 508 | BW12: 126 | BX12: 0 | BY12: 5236 | BZ12: 1117 | CA12: 76991
A13: Y1997 | B13: 17197 | C13: 743 | D13: 3442 | E13: 1834 | F13: 1203 | G13: 6042 | H13: 1156 | I13: 1723 | J13: 193 | K13: 558 | L13: 303 | M13: 890 | N13: 835 | O13: 55 | P13: 17150 | Q13: 546 | R13: 255 | S13: 11 | T13: 683 | U13: 19 | V13: 5225 | W13: 383 | X13: 9801 | Y13: 227 | Z13: 14966 | AA13: 8821 | AB13: 4102 | AC13: 2043 | AD13: 270 | AE13: 196 | AF13: 30 | AG13: 44 | AH13: 3213 | AI13: 143 | AJ13: 328 | AK13: 439 | AL13: 1058 | AM13: 298 | AN13: 21 | AO13: 318 | AP13: 162 | AQ13: 446 | AR13: 9917 | AS13: 510 | AT13: 163 | AU13: 107 | AV13: 416 | AW13: 626 | AX13: 783 | AY13: 1666 | AZ13: 4897 | BA13: 749 | BB13: 11314 | BC13: 1035 | BD13: 1189 | BE13: 221 | BF13: 1146 | BG13: 1674 | BH13: 987 | BI13: 1262 | BJ13: 1869 | BK13: 1931 | BL13: 3051 | BM13: 87 | BN13: 97 | BO13: 14 | BP13: 376 | BQ13: 59 | BR13: 710 | BS13: 665 | BT13: 1043 | BU13: 6802 | BV13: 530 | BW13: 128 | BX13: 1 | BY13: 4923 | BZ13: 1220 | CA13: 84770
A14: Y1998 | B14: 15152 | C14: 567 | D14: 3911 | E14: 2142 | F14: 1178 | G14: 5017 | H14: 1135 | I14: 180 | J14: 176 | K14: 545 | L14: 301 | M14: 1154 | N14: 1084 | O14: 70 | P14: 17908 | Q14: 510 | R14: 452 | S14: 10 | T14: 699 | U14: 22 | V14: 4503 | W14: 449 | X14: 11015 | Y14: 248 | Z14: 15078 | AA14: 9849 | AB14: 3374 | AC14: 1855 | AD14: 385 | AE14: 265 | AF14: 70 | AG14: 50 | AH14: 3388 | AI14: 139 | AJ14: 316 | AK14: 525 | AL14: 1225 | AM14: 283 | AN14: 32 | AO14: 237 | AP14: 164 | AQ14: 467 | AR14: 10428 | AS14: 497 | AT14: 169 | AU14: 104 | AV14: 421 | AW14: 593 | AX14: 698 | AY14: 1826 | AZ14: 5418 | BA14: 702 | BB14: 10656 | BC14: 808 | BD14: 1365 | BE14: 181 | BF14: 1034 | BG14: 1565 | BH14: 862 | BI14: 1277 | BJ14: 1863 | BK14: 1701 | BL14: 3345 | BM14: 85 | BN14: 98 | BO14: 12 | BP14: 365 | BQ14: 62 | BR14: 872 | BS14: 671 | BT14: 1180 | BU14: 11493 | BV14: 766 | BW14: 135 | BX14: 2 | BY14: 7642 | BZ14: 2948 | CA14: 88987
A15: Y1999 | B15: 15878 | C15: 698 | D15: 4163 | E15: 2209 | F15: 1387 | G15: 4882 | H15: 1192 | I15: 164 | J15: 213 | K15: 626 | L15: 344 | M15: 1402 | N15: 1345 | O15: 57 | P15: 16669 | Q15: 343 | R15: 777 | S15: 13 | T15: 698 | U15: 30 | V15: 3972 | W15: 415 | X15: 10164 | Y15: 257 | Z15: 14460 | AA15: 8406 | AB15: 4174 | AC15: 1880 | AD15: 328 | AE15: 226 | AF15: 51 | AG15: 51 | AH15: 3855 | AI15: 159 | AJ15: 380 | AK15: 524 | AL15: 1481 | AM15: 334 | AN15: 31 | AO15: 232 | AP15: 178 | AQ15: 536 | AR15: 10684 | AS15: 430 | AT15: 180 | AU15: 138 | AV15: 470 | AW15: 604 | AX15: 868 | AY15: 1362 | AZ15: 5974 | BA15: 658 | BB15: 10988 | BC15: 793 | BD15: 1096 | BE15: 197 | BF15: 1029 | BG15: 1405 | BH15: 906 | BI15: 1298 | BJ15: 2441 | BK15: 1823 | BL15: 3618 | BM15: 77 | BN15: 127 | BO15: 12 | BP15: 331 | BQ15: 63 | BR15: 1004 | BS15: 784 | BT15: 1220 | BU15: 9018 | BV15: 1807 | BW15: 98 | BX15: 8 | BY15: 4810 | BZ15: 2295 | CA15: 86900
... A39: Y2023 | B39: 54927 | C39: 1239 | D39: 17910 | E39: 3010 | F39: 1351 | G39: 20643 | H39: 5915 | I39: 294 | J39: 497 | K39: 1746 | L39: 2322 | M39: 2569 | N39: 2545 | O39: 24 | P39: 202833 | Q39: 454 | R39: 5507 | S39: 14 | T39: 1442 | U39: 206 | V39: 7452 | W39: 19318 | X39: 167787 | Y39: 653 | Z39: 194429 | AA39: 101958 | AB39: 15802 | AC39: 76669 | AD39: 1610 | AE39: 1052 | AF39: 422 | AG39: 136 | AH39: 11510 | AI39: 223 | AJ39: 1263 | AK39: 924 | AL39: 4753 | AM39: 1695 | AN39: 338 | AO39: 266 | AP39: 387 | AQ39: 1661 | AR39: 19417 | AS39: 111 | AT39: 398 | AU39: 99 | AV39: 893 | AW39: 366 | AX39: 858 | AY39: 1166 | AZ39: 14075 | BA39: 1451 | BB39: 18668 | BC39: 1303 | BD39: 2127 | BE39: 273 | BF39: 3059 | BG39: 1488 | BH39: 2683 | BI39: 2963 | BJ39: 2190 | BK39: 2582 | BL39: 10537 | BM39: 170 | BN39: 189 | BO39: 189 | BP39: 702 | BQ39: 183 | BR39: 4878 | BS39: 578 | BT39: 3648 | BU39: 41294 | BV39: 616 | BW39: 2011 | BX39: 11 | BY39: 28353 | BZ39: 10303 | CA39: 557794
